<?xml version="1.0"?>
<robot name="DummyRobot">
  <link name="trunk_link">
    <inertial>
      <mass value="1.0"/>
      <inertia ixx="1" ixy="0" ixz="0" iyy="1" iyz="0" izz="1"/>
    </inertial>
  </link>
  <link name="right_hip_yaw_link">
    <inertial>
      <mass value="1.0"/>
      <inertia ixx="1" ixy="0" ixz="0" iyy="1" iyz="0" izz="1"/>
    </inertial>
  </link>
  <link name="right_hip_roll_link">
    <inertial>
      <mass value="1.0"/>
      <inertia ixx="1" ixy="0" ixz="0" iyy="1" iyz="0" izz="1"/>
    </inertial>
  </link>
  <link name="right_hip_pitch_link">
    <inertial>
      <mass value="1.0"/>
      <inertia ixx="1" ixy="0" ixz="0" iyy="1" iyz="0" izz="1"/>
    </inertial>
  </link>
  <link name="right_knee_link">
    <inertial>
      <mass value="1.0"/>
      <inertia ixx="1" ixy="0" ixz="0" iyy="1" iyz="0" izz="1"/>
    </inertial>
  </link>
  <link name="right_ankle_pitch_link">
    <inertial>
      <mass value="1.0"/>
      <inertia ixx="1" ixy="0" ixz="0" iyy="1" iyz="0" izz="1"/>
    </inertial>
  </link>
  <link name="right_ankle_roll_link">
    <inertial>
      <mass value="1.0"/>
      <inertia ixx="1" ixy="0" ixz="0" iyy="1" iyz="0" izz="1"/>
    </inertial>
  </link>
  <link name="right_toe_link">
    <inertial>
      <mass value="1.0"/>
      <inertia ixx="1" ixy="0" ixz="0" iyy="1" iyz="0" izz="1"/>
    </inertial>
  </link>
  <link name="left_hip_yaw_link">
    <inertial>
      <mass value="1.0"/>
      <inertia ixx="1" ixy="0" ixz="0" iyy="1" iyz="0" izz="1"/>
    </inertial>
  </link>
  <link name="left_hip_roll_link">
    <inertial>
      <mass value="1.0"/>
      <inertia ixx="1" ixy="0" ixz="0" iyy="1" iyz="0" izz="1"/>
    </inertial>
  </link>
  <link name="left_hip_pitch_link">
    <inertial>
      <mass value="1.0"/>
      <inertia ixx="1" ixy="0" ixz="0" iyy="1" iyz="0" izz="1"/>
    </inertial>
  </link>
  <link name="left_knee_link">
    <inertial>
      <mass value="1.0"/>
      <inertia ixx="1" ixy="0" ixz="0" iyy="1" iyz="0" izz="1"/>
    </inertial>
  </link>
  <link name="left_ankle_pitch_link">
    <inertial>
      <mass value="1.0"/>
      <inertia ixx="1" ixy="0" ixz="0" iyy="1" iyz="0" izz="1"/>
    </inertial>
  </link>
  <link name="left_ankle_roll_link">
    <inertial>
      <mass value="1.0"/>
      <inertia ixx="1" ixy="0" ixz="0" iyy="1" iyz="0" izz="1"/>
    </inertial>
  </link>
  <link name="left_toe_link">
    <inertial>
      <mass value="1.0"/>
      <inertia ixx="1" ixy="0" ixz="0" iyy="1" iyz="0" izz="1"/>
    </inertial>
  </link>
  <link name="left_shoulder_pitch_link">
    <inertial>
      <mass value="1.0"/>
      <inertia ixx="1" ixy="0" ixz="0" iyy="1" iyz="0" izz="1"/>
    </inertial>
  </link>
  <link name="left_shoulder_roll_link">
    <inertial>
      <mass value="1.0"/>
      <inertia ixx="1" ixy="0" ixz="0" iyy="1" iyz="0" izz="1"/>
    </inertial>
  </link>
  <link name="left_elbow_link">
    <inertial>
      <mass value="1.0"/>
      <inertia ixx="1" ixy="0" ixz="0" iyy="1" iyz="0" izz="1"/>
    </inertial>
  </link>
  <link name="left_hand_link">
    <inertial>
      <mass value="1.0"/>
      <inertia ixx="1" ixy="0" ixz="0" iyy="1" iyz="0" izz="1"/>
    </inertial>
  </link>
  <link name="right_shoulder_pitch_link">
    <inertial>
      <mass value="1.0"/>
      <inertia ixx="1" ixy="0" ixz="0" iyy="1" iyz="0" izz="1"/>
    </inertial>
  </link>
  <link name="right_shoulder_roll_link">
    <inertial>
      <mass value="1.0"/>
      <inertia ixx="1" ixy="0" ixz="0" iyy="1" iyz="0" izz="1"/>
    </inertial>
  </link>
  <link name="right_elbow_link">
    <inertial>
      <mass value="1.0"/>
      <inertia ixx="1" ixy="0" ixz="0" iyy="1" iyz="0" izz="1"/>
    </inertial>
  </link>
  <link name="right_hand_link">
    <inertial>
      <mass value="1.0"/>
      <inertia ixx="1" ixy="0" ixz="0" iyy="1" iyz="0" izz="1"/>
    </inertial>
  </link>
  <link name="head_yaw_link">
    <inertial>
      <mass value="1.0"/>
      <inertia ixx="1" ixy="0" ixz="0" iyy="1" iyz="0" izz="1"/>
    </inertial>
  </link>
  <link name="head_pitch_link">
    <inertial>
      <mass value="1.0"/>
      <inertia ixx="1" ixy="0" ixz="0" iyy="1" iyz="0" izz="1"/>
    </inertial>
  </link>
  <joint name="right_hip_yaw" type="continuous">
    <origin xyz="0 -0.046375 0" rpy="0 0 0"/>
    <parent link="trunk_link"/>
    <child link="right_hip_yaw_link"/>
    <axis xyz="0 0 1"/>
  </joint>
  <joint name="right_hip_roll" type="continuous">
    <origin xyz="0 0 0" rpy="0 0 0"/>
    <parent link="right_hip_yaw_link"/>
    <child link="right_hip_roll_link"/>
    <axis xyz="1 0 0"/>
  </joint>
  <joint name="right_hip_pitch" type="continuous">
    <origin xyz="0 0 0" rpy="0 0 0"/>
    <parent link="right_hip_roll_link"/>
    <child link="right_hip_pitch_link"/>
    <axis xyz="0 1 0"/>
  </joint>
  <joint name="right_knee" type="continuous">
    <origin xyz="-0.014956 0 -0.249652" rpy="0 0 0"/>
    <parent link="right_hip_pitch_link"/>
    <child link="right_knee_link"/>
    <axis xyz="0 1 0"/>
  </joint>
  <joint name="right_ankle_pitch" type="continuous">
    <origin xyz="0 0 -0.25" rpy="0 0 0"/>
    <parent link="right_knee_link"/>
    <child link="right_ankle_pitch_link"/>
    <axis xyz="0 1 0"/>
  </joint>
  <joint name="right_ankle_roll" type="continuous">
    <origin xyz="0 0 0" rpy="0 0 0"/>
    <parent link="right_ankle_pitch_link"/>
    <child link="right_ankle_roll_link"/>
    <axis xyz="1 0 0"/>
  </joint>
  <joint name="right_toe" type="continuous">
    <origin xyz="0.10132 -0.015 -0.025" rpy="0 0 0"/>
    <parent link="right_ankle_roll_link"/>
    <child link="right_toe_link"/>
    <axis xyz="0 1 0"/>
  </joint>
  <joint name="left_hip_yaw" type="continuous">
    <origin xyz="0 0.046375 0" rpy="0 0 0"/>
    <parent link="trunk_link"/>
    <child link="left_hip_yaw_link"/>
    <axis xyz="0 0 1"/>
  </joint>
  <joint name="left_hip_roll" type="continuous">
    <origin xyz="0 0 0" rpy="0 0 0"/>
    <parent link="left_hip_yaw_link"/>
    <child link="left_hip_roll_link"/>
    <axis xyz="1 0 0"/>
  </joint>
  <joint name="left_hip_pitch" type="continuous">
    <origin xyz="0 0 0" rpy="0 0 0"/>
    <parent link="left_hip_roll_link"/>
    <child link="left_hip_pitch_link"/>
    <axis xyz="0 1 0"/>
  </joint>
  <joint name="left_knee" type="continuous">
    <origin xyz="-0.014956 0 -0.249652" rpy="0 0 0"/>
    <parent link="left_hip_pitch_link"/>
    <child link="left_knee_link"/>
    <axis xyz="0 1 0"/>
  </joint>
  <joint name="left_ankle_pitch" type="continuous">
    <origin xyz="0 0 -0.25" rpy="0 0 0"/>
    <parent link="left_knee_link"/>
    <child link="left_ankle_pitch_link"/>
    <axis xyz="0 1 0"/>
  </joint>
  <joint name="left_ankle_roll" type="continuous">
    <origin xyz="0 0 0" rpy="0 0 0"/>
    <parent link="left_ankle_pitch_link"/>
    <child link="left_ankle_roll_link"/>
    <axis xyz="1 0 0"/>
  </joint>
  <joint name="left_toe" type="continuous">
    <origin xyz="0.10132 0.015 -0.025" rpy="0 0 0"/>
    <parent link="left_ankle_roll_link"/>
    <child link="left_toe_link"/>
    <axis xyz="0 1 0"/>
  </joint>
  <joint name="left_shoulder_pitch" type="continuous">
    <origin xyz="0 0.07 0.2" rpy="0 0 0"/>
    <parent link="trunk_link"/>
    <child link="left_shoulder_pitch_link"/>
    <axis xyz="0 1 0"/>
  </joint>
  <joint name="left_shoulder_roll" type="continuous">
    <origin xyz="0 0 0" rpy="0 0 0"/>
    <parent link="left_shoulder_pitch_link"/>
    <child link="left_shoulder_roll_link"/>
    <axis xyz="1 0 0"/>
  </joint>
  <joint name="left_elbow" type="continuous">
    <origin xyz="0 0 -0.14" rpy="0 0 0"/>
    <parent link="left_shoulder_roll_link"/>
    <child link="left_elbow_link"/>
    <axis xyz="0 1 0"/>
  </joint>
  <joint name="left_hand" type="fixed">
    <origin xyz="0 0 -0.18" rpy="0 0 0"/>
    <parent link="left_elbow_link"/>
    <child link="left_hand_link"/>
  </joint>
  <joint name="right_shoulder_pitch" type="continuous">
    <origin xyz="0 -0.07 0.2" rpy="0 0 0"/>
    <parent link="trunk_link"/>
    <child link="right_shoulder_pitch_link"/>
    <axis xyz="0 1 0"/>
  </joint>
  <joint name="right_shoulder_roll" type="continuous">
    <origin xyz="0 0 0" rpy="0 0 0"/>
    <parent link="right_shoulder_pitch_link"/>
    <child link="right_shoulder_roll_link"/>
    <axis xyz="1 0 0"/>
  </joint>
  <joint name="right_elbow" type="continuous">
    <origin xyz="0 0 -0.14" rpy="0 0 0"/>
    <parent link="right_shoulder_roll_link"/>
    <child link="right_elbow_link"/>
    <axis xyz="0 1 0"/>
  </joint>
  <joint name="right_hand" type="fixed">
    <origin xyz="0 0 -0.18" rpy="0 0 0"/>
    <parent link="right_elbow_link"/>
    <child link="right_hand_link"/>
  </joint>
  <joint name="head_yaw" type="continuous">
    <origin xyz="0 0 0.21" rpy="0 0 0"/>
    <parent link="trunk_link"/>
    <child link="head_yaw_link"/>
    <axis xyz="0 0 1"/>
  </joint>
  <joint name="head_pitch" type="continuous">
    <origin xyz="0 0 -0.1" rpy="0 0 0"/>
    <parent link="head_yaw_link"/>
    <child link="head_pitch_link"/>
    <axis xyz="0 1 0"/>
  </joint>
  <link name="left_arch_tip">
    <inertial>
      <mass value="1.0"/>
      <inertia ixx="1" ixy="0" ixz="0" iyy="1" iyz="0" izz="1"/>
    </inertial>
  </link>
  <joint name="left_arch" type="fixed">
    <origin xyz="0.0216 0.015 -0.0667" rpy="0 0 0"/>
    <parent link="left_ankle_roll_link"/>
    <child link="left_arch_tip"/>
  </joint>
  <link name="left_toe_tip">
    <inertial>
      <mass value="1.0"/>
      <inertia ixx="1" ixy="0" ixz="0" iyy="1" iyz="0" izz="1"/>
    </inertial>
  </link>
  <joint name="left_toe_tip_joint" type="fixed">
    <origin xyz="0.021 0 -0.0417" rpy="0 0 0"/>
    <parent link="left_toe_link"/>
    <child link="left_toe_tip"/>
  </joint>
  <link name="right_arch_tip">
    <inertial>
      <mass value="1.0"/>
      <inertia ixx="1" ixy="0" ixz="0" iyy="1" iyz="0" izz="1"/>
    </inertial>
  </link>
  <joint name="right_arch" type="fixed">
    <origin xyz="0.0216 -0.015 -0.0667" rpy="0 0 0"/>
    <parent link="right_ankle_roll_link"/>
    <child link="right_arch_tip"/>
  </joint>
  <link name="right_toe_tip">
    <inertial>
      <mass value="1.0"/>
      <inertia ixx="1" ixy="0" ixz="0" iyy="1" iyz="0" izz="1"/>
    </inertial>
  </link>
  <joint name="right_toe_tip_joint" type="fixed">
    <origin xyz="0.021 0 -0.0417" rpy="0 0 0"/>
    <parent link="right_toe_link"/>
    <child link="right_toe_tip"/>
  </joint>
</robot>
       
